<mujoco model="ant">
  <compiler angle="degree" coordinate="local" inertiafromgeom="true" />
  <option integrator="RK4" timestep="0.02" />
  <custom>
    <numeric data="0.0 0.0 0.55 1.0 0.0 0.0 0.0 0.0 1.0 0.0 -1.0 0.0 -1.0 0.0 1.0" name="init_qpos" />
  </custom>
  <default>
    <joint armature="1" damping="1" limited="true" />
    <geom conaffinity="0" condim="3" density="5.0" friction="1 0.5 0.5" margin="0.01" rgba="0.8 0.6 0.4 1" solimp=".8 .8 .01" solref=".02 1" />
  </default>
  <asset>
    <texture builtin="gradient" height="100" rgb1="1 1 1" rgb2="0 0 0" type="skybox" width="100" />
    <texture builtin="flat" height="1278" mark="cross" markrgb="1 1 1" name="texgeom" random="0.01" rgb1="0.8 0.6 0.4" rgb2="0.8 0.6 0.4" type="cube" width="127" />
    <texture builtin="checker" height="100" name="texplane" rgb1="0 0 0" rgb2="0.8 0.8 0.8" type="2d" width="100" />
    <material name="MatPlane" reflectance="0.5" shininess="1" specular="1" texrepeat="60 60" texture="texplane" />
    <material name="geom" texture="texgeom" texuniform="true" />
  </asset>
  <worldbody>
    <light cutoff="100" diffuse="1 1 1" dir="-0 0 -1.3" directional="true" exponent="1" pos="0 0 1.3" specular=".1 .1 .1" />
    <geom conaffinity="1" condim="3" name="floor" pos="0 0 0" rgba="0.8 0.9 0.8 1" size="40 40 40" type="plane" />
    <body name="torso" pos="0 0 0.75">
      <geom name="torso_geom" pos="0 0 0" size="0.25" type="sphere" />
      <joint armature="0" axis="0 0 1" damping="0" limited="false" margin="0.01" name="root" pos="0 0 0" type="free" />
      <body name="front_left_leg" pos="0 0 0">
        <geom fromto="0.0 0.0 0.0 0.2 0.2 0.0" name="aux_1_geom" size="0.08" type="capsule" />
        <body name="aux_1" pos="0.2 0.2 0">
          <joint axis="0 0 1" name="hip_1" pos="0.0 0.0 0.0" range="-30 30" type="hinge" />
          <geom fromto="0.0 0.0 0.0 0.2 0.2 0.0" name="left_leg_geom" size="0.08" type="capsule" />
          <body pos="0.2 0.2 0">
            <joint axis="-1 1 0" name="ankle_1" pos="0.0 0.0 0.0" range="30 70" type="hinge" />
            <geom fromto="0.0 0.0 0.0 0.4 0.4 0.0" name="left_ankle_geom" size="0.08" type="capsule" />
          </body>
        </body>
      </body>
      <body name="front_right_leg" pos="0 0 0">
        <geom fromto="0.0 0.0 0.0 -0.2 0.2 0.0" name="aux_2_geom" size="0.08" type="capsule" />
        <body name="aux_2" pos="-0.2 0.2 0">
          <joint axis="0 0 1" name="hip_2" pos="0.0 0.0 0.0" range="-30 30" type="hinge" />
          <geom fromto="0.0 0.0 0.0 -0.2 0.2 0.0" name="right_leg_geom" size="0.08" type="capsule" />
          <body pos="-0.2 0.2 0">
            <joint axis="1 1 0" name="ankle_2" pos="0.0 0.0 0.0" range="-70 -30" type="hinge" />
            <geom fromto="0.0 0.0 0.0 -0.4 0.4 0.0" name="right_ankle_geom" size="0.08" type="capsule" />
          </body>
        </body>
      </body>
      <body name="back_leg" pos="0 0 0">
        <geom fromto="0.0 0.0 0.0 -0.2 -0.2 0.0" name="aux_3_geom" size="0.08" type="capsule" />
        <body name="aux_3" pos="-0.2 -0.2 0">
          <joint axis="0 0 1" name="hip_3" pos="0.0 0.0 0.0" range="-30 30" type="hinge" />
          <geom fromto="0.0 0.0 0.0 -0.2 -0.2 0.0" name="back_leg_geom" size="0.08" type="capsule" />
          <body pos="-0.2 -0.2 0">
            <joint axis="-1 1 0" name="ankle_3" pos="0.0 0.0 0.0" range="-70 -30" type="hinge" />
            <geom fromto="0.0 0.0 0.0 -0.4 -0.4 0.0" name="third_ankle_geom" size="0.08" type="capsule" />
          </body>
        </body>
      </body>
      <body name="right_back_leg" pos="0 0 0">
        <geom fromto="0.0 0.0 0.0 0.2 -0.2 0.0" name="aux_4_geom" size="0.08" type="capsule" />
        <body name="aux_4" pos="0.2 -0.2 0">
          <joint axis="0 0 1" name="hip_4" pos="0.0 0.0 0.0" range="-30 30" type="hinge" />
          <geom fromto="0.0 0.0 0.0 0.2 -0.2 0.0" name="rightback_leg_geom" size="0.08" type="capsule" />
          <body pos="0.2 -0.2 0">
            <joint axis="1 1 0" name="ankle_4" pos="0.0 0.0 0.0" range="30 70" type="hinge" />
            <geom fromto="0.0 0.0 0.0 0.4 -0.4 0.0" name="fourth_ankle_geom" size="0.08" type="capsule" />
          </body>
        </body>
      </body>
    </body>

  <geom conaffinity="1" contype="1" material="" name="block_0_0" pos="-11.000000 -11.000000 1.000000" rgba="0.4 0.4 0.4 1" size="0.500000 0.500000 1.000000" type="box" /><geom conaffinity="1" contype="1" material="" name="block_0_1" pos="-10.000000 -11.000000 1.000000" rgba="0.4 0.4 0.4 1" size="0.500000 0.500000 1.000000" type="box" /><geom conaffinity="1" contype="1" material="" name="block_0_2" pos="-9.000000 -11.000000 1.000000" rgba="0.4 0.4 0.4 1" size="0.500000 0.500000 1.000000" type="box" /><geom conaffinity="1" contype="1" material="" name="block_0_3" pos="-8.000000 -11.000000 1.000000" rgba="0.4 0.4 0.4 1" size="0.500000 0.500000 1.000000" type="box" /><geom conaffinity="1" contype="1" material="" name="block_0_4" pos="-7.000000 -11.000000 1.000000" rgba="0.4 0.4 0.4 1" size="0.500000 0.500000 1.000000" type="box" /><geom conaffinity="1" contype="1" material="" name="block_0_5" pos="-6.000000 -11.000000 1.000000" rgba="0.4 0.4 0.4 1" size="0.500000 0.500000 1.000000" type="box" /><geom conaffinity="1" contype="1" material="" name="block_0_6" pos="-5.000000 -11.000000 1.000000" rgba="0.4 0.4 0.4 1" size="0.500000 0.500000 1.000000" type="box" /><geom conaffinity="1" contype="1" material="" name="block_0_7" pos="-4.000000 -11.000000 1.000000" rgba="0.4 0.4 0.4 1" size="0.500000 0.500000 1.000000" type="box" /><geom conaffinity="1" contype="1" material="" name="block_0_8" pos="-3.000000 -11.000000 1.000000" rgba="0.4 0.4 0.4 1" size="0.500000 0.500000 1.000000" type="box" /><geom conaffinity="1" contype="1" material="" name="block_0_9" pos="-2.000000 -11.000000 1.000000" rgba="0.4 0.4 0.4 1" size="0.500000 0.500000 1.000000" type="box" /><geom conaffinity="1" contype="1" material="" name="block_0_10" pos="-1.000000 -11.000000 1.000000" rgba="0.4 0.4 0.4 1" size="0.500000 0.500000 1.000000" type="box" /><geom conaffinity="1" contype="1" material="" name="block_0_11" pos="0.000000 -11.000000 1.000000" rgba="0.4 0.4 0.4 1" size="0.500000 0.500000 1.000000" type="box" /><geom conaffinity="1" contype="1" material="" name="block_0_12" pos="1.000000 -11.000000 1.000000" rgba="0.4 0.4 0.4 1" size="0.500000 0.500000 1.000000" type="box" /><geom conaffinity="1" contype="1" material="" name="block_0_13" pos="2.000000 -11.000000 1.000000" rgba="0.4 0.4 0.4 1" size="0.500000 0.500000 1.000000" type="box" /><geom conaffinity="1" contype="1" material="" name="block_0_14" pos="3.000000 -11.000000 1.000000" rgba="0.4 0.4 0.4 1" size="0.500000 0.500000 1.000000" type="box" /><geom conaffinity="1" contype="1" material="" name="block_0_15" pos="4.000000 -11.000000 1.000000" rgba="0.4 0.4 0.4 1" size="0.500000 0.500000 1.000000" type="box" /><geom conaffinity="1" contype="1" material="" name="block_0_16" pos="5.000000 -11.000000 1.000000" rgba="0.4 0.4 0.4 1" size="0.500000 0.500000 1.000000" type="box" /><geom conaffinity="1" contype="1" material="" name="block_0_17" pos="6.000000 -11.000000 1.000000" rgba="0.4 0.4 0.4 1" size="0.500000 0.500000 1.000000" type="box" /><geom conaffinity="1" contype="1" material="" name="block_0_18" pos="7.000000 -11.000000 1.000000" rgba="0.4 0.4 0.4 1" size="0.500000 0.500000 1.000000" type="box" /><geom conaffinity="1" contype="1" material="" name="block_1_0" pos="-11.000000 -10.000000 1.000000" rgba="0.4 0.4 0.4 1" size="0.500000 0.500000 1.000000" type="box" /><geom conaffinity="1" contype="1" material="" name="block_1_18" pos="7.000000 -10.000000 1.000000" rgba="0.4 0.4 0.4 1" size="0.500000 0.500000 1.000000" type="box" /><geom conaffinity="1" contype="1" material="" name="block_2_0" pos="-11.000000 -9.000000 1.000000" rgba="0.4 0.4 0.4 1" size="0.500000 0.500000 1.000000" type="box" /><geom conaffinity="1" contype="1" material="" name="block_2_18" pos="7.000000 -9.000000 1.000000" rgba="0.4 0.4 0.4 1" size="0.500000 0.500000 1.000000" type="box" /><geom conaffinity="1" contype="1" material="" name="block_3_0" pos="-11.000000 -8.000000 1.000000" rgba="0.4 0.4 0.4 1" size="0.500000 0.500000 1.000000" type="box" /><geom conaffinity="1" contype="1" material="" name="block_3_18" pos="7.000000 -8.000000 1.000000" rgba="0.4 0.4 0.4 1" size="0.500000 0.500000 1.000000" type="box" /><geom conaffinity="1" contype="1" material="" name="block_4_0" pos="-11.000000 -7.000000 1.000000" rgba="0.4 0.4 0.4 1" size="0.500000 0.500000 1.000000" type="box" /><geom conaffinity="1" contype="1" material="" name="block_4_18" pos="7.000000 -7.000000 1.000000" rgba="0.4 0.4 0.4 1" size="0.500000 0.500000 1.000000" type="box" /><geom conaffinity="1" contype="1" material="" name="block_5_0" pos="-11.000000 -6.000000 1.000000" rgba="0.4 0.4 0.4 1" size="0.500000 0.500000 1.000000" type="box" /><geom conaffinity="1" contype="1" material="" name="block_5_9" pos="-2.000000 -6.000000 1.000000" rgba="0.4 0.4 0.4 1" size="0.500000 0.500000 1.000000" type="box" /><geom conaffinity="1" contype="1" material="" name="block_5_18" pos="7.000000 -6.000000 1.000000" rgba="0.4 0.4 0.4 1" size="0.500000 0.500000 1.000000" type="box" /><geom conaffinity="1" contype="1" material="" name="block_6_0" pos="-11.000000 -5.000000 1.000000" rgba="0.4 0.4 0.4 1" size="0.500000 0.500000 1.000000" type="box" /><geom conaffinity="1" contype="1" material="" name="block_6_9" pos="-2.000000 -5.000000 1.000000" rgba="0.4 0.4 0.4 1" size="0.500000 0.500000 1.000000" type="box" /><geom conaffinity="1" contype="1" material="" name="block_6_18" pos="7.000000 -5.000000 1.000000" rgba="0.4 0.4 0.4 1" size="0.500000 0.500000 1.000000" type="box" /><geom conaffinity="1" contype="1" material="" name="block_7_0" pos="-11.000000 -4.000000 1.000000" rgba="0.4 0.4 0.4 1" size="0.500000 0.500000 1.000000" type="box" /><geom conaffinity="1" contype="1" material="" name="block_7_9" pos="-2.000000 -4.000000 1.000000" rgba="0.4 0.4 0.4 1" size="0.500000 0.500000 1.000000" type="box" /><geom conaffinity="1" contype="1" material="" name="block_7_18" pos="7.000000 -4.000000 1.000000" rgba="0.4 0.4 0.4 1" size="0.500000 0.500000 1.000000" type="box" /><geom conaffinity="1" contype="1" material="" name="block_8_0" pos="-11.000000 -3.000000 1.000000" rgba="0.4 0.4 0.4 1" size="0.500000 0.500000 1.000000" type="box" /><geom conaffinity="1" contype="1" material="" name="block_8_9" pos="-2.000000 -3.000000 1.000000" rgba="0.4 0.4 0.4 1" size="0.500000 0.500000 1.000000" type="box" /><geom conaffinity="1" contype="1" material="" name="block_8_18" pos="7.000000 -3.000000 1.000000" rgba="0.4 0.4 0.4 1" size="0.500000 0.500000 1.000000" type="box" /><geom conaffinity="1" contype="1" material="" name="block_9_0" pos="-11.000000 -2.000000 1.000000" rgba="0.4 0.4 0.4 1" size="0.500000 0.500000 1.000000" type="box" /><geom conaffinity="1" contype="1" material="" name="block_9_5" pos="-6.000000 -2.000000 1.000000" rgba="0.4 0.4 0.4 1" size="0.500000 0.500000 1.000000" type="box" /><geom conaffinity="1" contype="1" material="" name="block_9_6" pos="-5.000000 -2.000000 1.000000" rgba="0.4 0.4 0.4 1" size="0.500000 0.500000 1.000000" type="box" /><geom conaffinity="1" contype="1" material="" name="block_9_7" pos="-4.000000 -2.000000 1.000000" rgba="0.4 0.4 0.4 1" size="0.500000 0.500000 1.000000" type="box" /><geom conaffinity="1" contype="1" material="" name="block_9_8" pos="-3.000000 -2.000000 1.000000" rgba="0.4 0.4 0.4 1" size="0.500000 0.500000 1.000000" type="box" /><geom conaffinity="1" contype="1" material="" name="block_9_9" pos="-2.000000 -2.000000 1.000000" rgba="0.4 0.4 0.4 1" size="0.500000 0.500000 1.000000" type="box" /><geom conaffinity="1" contype="1" material="" name="block_9_10" pos="-1.000000 -2.000000 1.000000" rgba="0.4 0.4 0.4 1" size="0.500000 0.500000 1.000000" type="box" /><geom conaffinity="1" contype="1" material="" name="block_9_11" pos="0.000000 -2.000000 1.000000" rgba="0.4 0.4 0.4 1" size="0.500000 0.500000 1.000000" type="box" /><geom conaffinity="1" contype="1" material="" name="block_9_12" pos="1.000000 -2.000000 1.000000" rgba="0.4 0.4 0.4 1" size="0.500000 0.500000 1.000000" type="box" /><geom conaffinity="1" contype="1" material="" name="block_9_13" pos="2.000000 -2.000000 1.000000" rgba="0.4 0.4 0.4 1" size="0.500000 0.500000 1.000000" type="box" /><geom conaffinity="1" contype="1" material="" name="block_9_18" pos="7.000000 -2.000000 1.000000" rgba="0.4 0.4 0.4 1" size="0.500000 0.500000 1.000000" type="box" /><geom conaffinity="1" contype="1" material="" name="block_10_0" pos="-11.000000 -1.000000 1.000000" rgba="0.4 0.4 0.4 1" size="0.500000 0.500000 1.000000" type="box" /><geom conaffinity="1" contype="1" material="" name="block_10_9" pos="-2.000000 -1.000000 1.000000" rgba="0.4 0.4 0.4 1" size="0.500000 0.500000 1.000000" type="box" /><geom conaffinity="1" contype="1" material="" name="block_10_18" pos="7.000000 -1.000000 1.000000" rgba="0.4 0.4 0.4 1" size="0.500000 0.500000 1.000000" type="box" /><geom conaffinity="1" contype="1" material="" name="block_11_0" pos="-11.000000 0.000000 1.000000" rgba="0.4 0.4 0.4 1" size="0.500000 0.500000 1.000000" type="box" /><geom conaffinity="1" contype="1" material="" name="block_11_9" pos="-2.000000 0.000000 1.000000" rgba="0.4 0.4 0.4 1" size="0.500000 0.500000 1.000000" type="box" /><geom conaffinity="1" contype="1" material="" name="block_11_18" pos="7.000000 0.000000 1.000000" rgba="0.4 0.4 0.4 1" size="0.500000 0.500000 1.000000" type="box" /><geom conaffinity="1" contype="1" material="" name="block_12_0" pos="-11.000000 1.000000 1.000000" rgba="0.4 0.4 0.4 1" size="0.500000 0.500000 1.000000" type="box" /><geom conaffinity="1" contype="1" material="" name="block_12_9" pos="-2.000000 1.000000 1.000000" rgba="0.4 0.4 0.4 1" size="0.500000 0.500000 1.000000" type="box" /><geom conaffinity="1" contype="1" material="" name="block_12_18" pos="7.000000 1.000000 1.000000" rgba="0.4 0.4 0.4 1" size="0.500000 0.500000 1.000000" type="box" /><geom conaffinity="1" contype="1" material="" name="block_13_0" pos="-11.000000 2.000000 1.000000" rgba="0.4 0.4 0.4 1" size="0.500000 0.500000 1.000000" type="box" /><geom conaffinity="1" contype="1" material="" name="block_13_9" pos="-2.000000 2.000000 1.000000" rgba="0.4 0.4 0.4 1" size="0.500000 0.500000 1.000000" type="box" /><geom conaffinity="1" contype="1" material="" name="block_13_18" pos="7.000000 2.000000 1.000000" rgba="0.4 0.4 0.4 1" size="0.500000 0.500000 1.000000" type="box" /><geom conaffinity="1" contype="1" material="" name="block_14_0" pos="-11.000000 3.000000 1.000000" rgba="0.4 0.4 0.4 1" size="0.500000 0.500000 1.000000" type="box" /><geom conaffinity="1" contype="1" material="" name="block_14_18" pos="7.000000 3.000000 1.000000" rgba="0.4 0.4 0.4 1" size="0.500000 0.500000 1.000000" type="box" /><geom conaffinity="1" contype="1" material="" name="block_15_0" pos="-11.000000 4.000000 1.000000" rgba="0.4 0.4 0.4 1" size="0.500000 0.500000 1.000000" type="box" /><geom conaffinity="1" contype="1" material="" name="block_15_18" pos="7.000000 4.000000 1.000000" rgba="0.4 0.4 0.4 1" size="0.500000 0.500000 1.000000" type="box" /><geom conaffinity="1" contype="1" material="" name="block_16_0" pos="-11.000000 5.000000 1.000000" rgba="0.4 0.4 0.4 1" size="0.500000 0.500000 1.000000" type="box" /><geom conaffinity="1" contype="1" material="" name="block_16_18" pos="7.000000 5.000000 1.000000" rgba="0.4 0.4 0.4 1" size="0.500000 0.500000 1.000000" type="box" /><geom conaffinity="1" contype="1" material="" name="block_17_0" pos="-11.000000 6.000000 1.000000" rgba="0.4 0.4 0.4 1" size="0.500000 0.500000 1.000000" type="box" /><geom conaffinity="1" contype="1" material="" name="block_17_18" pos="7.000000 6.000000 1.000000" rgba="0.4 0.4 0.4 1" size="0.500000 0.500000 1.000000" type="box" /><geom conaffinity="1" contype="1" material="" name="block_18_0" pos="-11.000000 7.000000 1.000000" rgba="0.4 0.4 0.4 1" size="0.500000 0.500000 1.000000" type="box" /><geom conaffinity="1" contype="1" material="" name="block_18_1" pos="-10.000000 7.000000 1.000000" rgba="0.4 0.4 0.4 1" size="0.500000 0.500000 1.000000" type="box" /><geom conaffinity="1" contype="1" material="" name="block_18_2" pos="-9.000000 7.000000 1.000000" rgba="0.4 0.4 0.4 1" size="0.500000 0.500000 1.000000" type="box" /><geom conaffinity="1" contype="1" material="" name="block_18_3" pos="-8.000000 7.000000 1.000000" rgba="0.4 0.4 0.4 1" size="0.500000 0.500000 1.000000" type="box" /><geom conaffinity="1" contype="1" material="" name="block_18_4" pos="-7.000000 7.000000 1.000000" rgba="0.4 0.4 0.4 1" size="0.500000 0.500000 1.000000" type="box" /><geom conaffinity="1" contype="1" material="" name="block_18_5" pos="-6.000000 7.000000 1.000000" rgba="0.4 0.4 0.4 1" size="0.500000 0.500000 1.000000" type="box" /><geom conaffinity="1" contype="1" material="" name="block_18_6" pos="-5.000000 7.000000 1.000000" rgba="0.4 0.4 0.4 1" size="0.500000 0.500000 1.000000" type="box" /><geom conaffinity="1" contype="1" material="" name="block_18_7" pos="-4.000000 7.000000 1.000000" rgba="0.4 0.4 0.4 1" size="0.500000 0.500000 1.000000" type="box" /><geom conaffinity="1" contype="1" material="" name="block_18_8" pos="-3.000000 7.000000 1.000000" rgba="0.4 0.4 0.4 1" size="0.500000 0.500000 1.000000" type="box" /><geom conaffinity="1" contype="1" material="" name="block_18_9" pos="-2.000000 7.000000 1.000000" rgba="0.4 0.4 0.4 1" size="0.500000 0.500000 1.000000" type="box" /><geom conaffinity="1" contype="1" material="" name="block_18_10" pos="-1.000000 7.000000 1.000000" rgba="0.4 0.4 0.4 1" size="0.500000 0.500000 1.000000" type="box" /><geom conaffinity="1" contype="1" material="" name="block_18_11" pos="0.000000 7.000000 1.000000" rgba="0.4 0.4 0.4 1" size="0.500000 0.500000 1.000000" type="box" /><geom conaffinity="1" contype="1" material="" name="block_18_12" pos="1.000000 7.000000 1.000000" rgba="0.4 0.4 0.4 1" size="0.500000 0.500000 1.000000" type="box" /><geom conaffinity="1" contype="1" material="" name="block_18_13" pos="2.000000 7.000000 1.000000" rgba="0.4 0.4 0.4 1" size="0.500000 0.500000 1.000000" type="box" /><geom conaffinity="1" contype="1" material="" name="block_18_14" pos="3.000000 7.000000 1.000000" rgba="0.4 0.4 0.4 1" size="0.500000 0.500000 1.000000" type="box" /><geom conaffinity="1" contype="1" material="" name="block_18_15" pos="4.000000 7.000000 1.000000" rgba="0.4 0.4 0.4 1" size="0.500000 0.500000 1.000000" type="box" /><geom conaffinity="1" contype="1" material="" name="block_18_16" pos="5.000000 7.000000 1.000000" rgba="0.4 0.4 0.4 1" size="0.500000 0.500000 1.000000" type="box" /><geom conaffinity="1" contype="1" material="" name="block_18_17" pos="6.000000 7.000000 1.000000" rgba="0.4 0.4 0.4 1" size="0.500000 0.500000 1.000000" type="box" /><geom conaffinity="1" contype="1" material="" name="block_18_18" pos="7.000000 7.000000 1.000000" rgba="0.4 0.4 0.4 1" size="0.500000 0.500000 1.000000" type="box" /></worldbody>
  <actuator>
    <motor ctrllimited="true" ctrlrange="-1.0 1.0" gear="150" joint="hip_4" />
    <motor ctrllimited="true" ctrlrange="-1.0 1.0" gear="150" joint="ankle_4" />
    <motor ctrllimited="true" ctrlrange="-1.0 1.0" gear="150" joint="hip_1" />
    <motor ctrllimited="true" ctrlrange="-1.0 1.0" gear="150" joint="ankle_1" />
    <motor ctrllimited="true" ctrlrange="-1.0 1.0" gear="150" joint="hip_2" />
    <motor ctrllimited="true" ctrlrange="-1.0 1.0" gear="150" joint="ankle_2" />
    <motor ctrllimited="true" ctrlrange="-1.0 1.0" gear="150" joint="hip_3" />
    <motor ctrllimited="true" ctrlrange="-1.0 1.0" gear="150" joint="ankle_3" />
  </actuator>
</mujoco>